Workbook
Name a: #REF!

Sheet Completati dal 2014
A1: Apertura Ticket | B1: Utente | C1: Status | D1: In carico a | E1: Brand | F1: Modello | G1: Data Arrivo | H1: Nome | I1: Cespite | J1: PSW CIRESON | K1: Data pianificazione | L1: Mail | M1: SCSM | N1: ARS | O1: Delivery | P1: Note | Q1: Scorta | R1: Conteggio pc | S1: Conteggio pc in lavorazione | T1: Problema Webcam Lenovo
A2: SR964075 | B2: Lunardelli, Piergiorgio (ITDGTOL00059116) | E2: Hewlett-Packard | F2: HP EliteBook 840 G6 | G2: 43728 | H2: ITDGTOL00069400 | I2: 69400 | J2: Giaveno69400 | K2: OK | L2: OK | M2: OK | N2: OK | T2: =_xlfn.XLOOKUP(H2,#REF!,#REF!,0,0) -> #REF!
A3: SR974804 | B3: Uso gen.Manutenzione(ITDGTOC00059302) Monchietto, Guido | E3: Hewlett-Packard | F3: HP EliteBook 840 G6 | G3: 43728 | H3: ITDGTOL00069401 | I3: 69401 | J3: Vomero69401 | K3: OK | L3: OK | N3: OK | T3: =_xlfn.XLOOKUP(H3,#REF!,#REF!,0,0) -> #REF!
A4: SR977729 | B4: Wiedner, Sunhilde (ITDGTOL00059368) | E4: Hewlett-Packard | F4: HP EliteBook 840 G6 | G4: 43728 | H4: ITDGTOL00069403 | I4: 69403 | J4: Italia69403 | K4: OK | L4: OK | M4: OK | N4: OK | T4: =_xlfn.XLOOKUP(H4,#REF!,#REF!,0,0) -> #REF!
A5: SR978321 | B5: Giai Merlera, Davide (ITDGTOL00059074) | E5: Hewlett-Packard | F5: HP EliteBook 840 G6 | G5: 43728 | H5: ITDGTOL00069406 | I5: 69406 | J5: Parigi69406 | K5: OK | L5: OK | N5: OK | T5: =_xlfn.XLOOKUP(H5,#REF!,#REF!,0,0) -> #REF!
A6: SR982043 | B6: Pizzitelli, Roberta (ITDGTOL00059363) | E6: Hewlett-Packard | F6: HP EliteBook 840 G6 | G6: 43728 | H6: ITDGTOL00069407 | I6: 69407 | J6: Venezia34 | K6: OK | L6: OK | N6: OK | T6: =_xlfn.XLOOKUP(H6,#REF!,#REF!,0,0) -> #REF!
A7: SR982049 | B7: Cotugno, Cosimo (ITDGTOC00059299) | E7: Hewlett-Packard | F7: HP EliteBook 840 G6 | G7: 43728 | H7: ITDGTOL00069408 | I7: 69408 | J7: Palermo77 | K7: OK | L7: OK | N7: OK | T7: =_xlfn.XLOOKUP(H7,#REF!,#REF!,0,0) -> #REF!
A8: SR983451 | B8: Ficco Davide (IDG2466 - Vedi note CMDB) | E8: Hewlett-Packard | F8: HP EliteBook 840 G6 | G8: 43728 | H8: ITDGTOL00069409 | I8: 69409 | J8: Artico57 | K8: OK | L8: OK | N8: OK | T8: =_xlfn.XLOOKUP(H8,#REF!,#REF!,0,0) -> #REF!
A9: SR983457 | B9: Latu Patrice (ITDGTOL00058590) | E9: Hewlett-Packard | F9: HP EliteBook 840 G6 | G9: 43728 | H9: ITDGTOL00069410 | I9: 69410 | J9: Bologna36 | K9: OK | L9: OK | M9: OK | N9: OK | T9: =_xlfn.XLOOKUP(H9,#REF!,#REF!,0,0) -> #REF!
B10: De Giorgis (ITDGTOC00060174) | E10: Hewlett-Packard | F10: HP EliteBook 840 G6 | G10: 43728 | H10: ITDGTOL00069411 | I10: 69411 | K10: In Corso | T10: =_xlfn.XLOOKUP(H10,#REF!,#REF!,0,0) -> #REF!
A11: SR956982 | B11: Cappello Lorenza (ITDGTOL00060225) | E11: Hewlett-Packard | F11: HP EliteBook 840 G6 | G11: 43728 | H11: ITDGTOL00069412 | I11: 69412 | J11: Macchina19 | K11: OK | L11: OK | N11: OK | T11: =_xlfn.XLOOKUP(H11,#REF!,#REF!,0,0) -> #REF!
A12: SR971925 | B12: Vigilante Raffele IG/P-S ITDGTOL00059115 | E12: Hewlett-Packard | F12: HP EliteBook 840 G6 | G12: 43728 | H12: ITDGTOL00069413 | I12: 69413 | J12: Livorno413 | K12: OK | L12: OK | M12: OK | N12: OK | T12: =_xlfn.XLOOKUP(H12,#REF!,#REF!,0,0) -> #REF!
A13: SR952940 | B13: Ozdemir, Fuat (ITDGTOL00059371) | E13: Hewlett-Packard | F13: HP EliteBook 840 G6 | G13: 43728 | H13: ITDGTOL00069419 | I13: 69419 | J13: EstRal19 | K13: OK | L13: OK | N13: OK | T13: =_xlfn.XLOOKUP(H13,#REF!,#REF!,0,0) -> #REF!
A14: SR951643 | B14: Del Rosso Marco (ITDGTOL00059109) | E14: Hewlett-Packard | F14: HP EliteBook 840 G6 | G14: 43728 | H14: ITDGTOL00069422 | I14: 69422 | J14: Cooler422 | K14: Ok | L14: OK | M14: OK | N14: OK | T14: =_xlfn.XLOOKUP(H14,#REF!,#REF!,0,0) -> #REF!
A15: SR965210 | B15: Damicis Claudio (ITDGTOC00059300) | E15: Hewlett-Packard | F15: HP EliteBook 840 G6 | G15: 43728 | H15: ITDGTOL00069426 | I15: 69426 | J15: Lorenzo19 | K15: OK | L15: OK | N15: OK | T15: =_xlfn.XLOOKUP(H15,#REF!,#REF!,0,0) -> #REF!
B16: Pelliccioni, Marco (ITDGTOL00059112) | E16: Hewlett-Packard | F16: HP EliteBook 840 G6 | G16: 43728 | H16: ITDGTOL00069431 | I16: 69431 | K16: In Corso | T16: =_xlfn.XLOOKUP(H16,#REF!,#REF!,0,0) -> #REF!
E17: Hewlett-Packard | F17: HP EliteBook 840 G6 | G17: 43728 | H17: ITDGTOL00069432 | I17: 69432 | K17: In Corso | T17: =_xlfn.XLOOKUP(H17,#REF!,#REF!,0,0) -> #REF!
E18: Hewlett-Packard | F18: HP EliteBook 840 G6 | G18: 43728 | H18: ITDGTOL00069433 | I18: 69433 | K18: In Corso | T18: =_xlfn.XLOOKUP(H18,#REF!,#REF!,0,0) -> #REF!
E19: Hewlett-Packard | F19: HP EliteBook 840 G6 | G19: 43728 | H19: ITDGTOL00069434 | I19: 69434 | K19: In Corso | T19: =_xlfn.XLOOKUP(H19,#REF!,#REF!,0,0) -> #REF!
E20: Hewlett-Packard | F20: HP EliteBook 840 G6 | G20: 43728 | H20: ITDGTOL00069435 | I20: 69435 | T20: =_xlfn.XLOOKUP(H20,#REF!,#REF!,0,0) -> #REF!
E21: Hewlett-Packard | F21: HP EliteBook 840 G6 | G21: 43728 | H21: ITDGTOL00069436 | I21: 69436 | T21: =_xlfn.XLOOKUP(H21,#REF!,#REF!,0,0) -> #REF!
B22: Favero Catia (IDG2460) | E22: Hewlett-Packard | F22: HP EliteBook 840 G6 | G22: 43728 | H22: ITDGTOL00069437 | I22: 69437 | L22: OK | T22: =_xlfn.XLOOKUP(H22,#REF!,#REF!,0,0) -> #REF!
B23: Sala Video Direzione (ITDGTOL00059068) | E23: Hewlett-Packard | F23: HP EliteBook 840 G6 | G23: 43728 | H23: ITDGTOL00069438 | I23: 69438 | T23: =_xlfn.XLOOKUP(H23,#REF!,#REF!,0,0) -> #REF!
B24: Bertazzoni Alessandro (ITDGTOL00058918) | E24: Hewlett-Packard | F24: HP EliteBook 840 G6 | G24: 43728 | H24: ITDGTOL00069439 | I24: 69439 | T24: =_xlfn.XLOOKUP(H24,#REF!,#REF!,0,0) -> #REF!
B25: A disposizione | E25: Hewlett-Packard | F25: HP EliteBook 840 G6 | G25: 43728 | H25: ITDGTOL00069440 | I25: 69440 | T25: =_xlfn.XLOOKUP(H25,#REF!,#REF!,0,0) -> #REF!
B26: A disposizione | E26: Hewlett-Packard | F26: HP EliteBook 840 G6 | G26: 43728 | H26: ITDGTOL00069441 | I26: 69441 | T26: =_xlfn.XLOOKUP(H26,#REF!,#REF!,0,0) -> #REF!
B27: A disposizione | E27: Hewlett-Packard | F27: HP EliteBook 840 G6 | G27: 43728 | H27: ITDGTOL00069442 | I27: 69442 | T27: =_xlfn.XLOOKUP(H27,#REF!,#REF!,0,0) -> #REF!
B28: A disposizione | E28: Hewlett-Packard | F28: HP EliteBook 840 G6 | G28: 43728 | H28: ITDGTOL00069443 | I28: 69443 | T28: =_xlfn.XLOOKUP(H28,#REF!,#REF!,0,0) -> #REF!
B29: A disposizione | E29: Hewlett-Packard | F29: HP EliteBook 840 G6 | G29: 43728 | H29: ITDGTOL00069444 | I29: 69444 | T29: =_xlfn.XLOOKUP(H29,#REF!,#REF!,0,0) -> #REF!
A30: SR922054 | B30: Vessis Costantino (ITDGTOL00059396) | D30: Finelli Antonella | E30: Hewlett-Packard | F30: HP ZBook 15 G5 | G30: 43563 | H30: ITDGTOL00069198 | I30: 69198 | J30: Security69198 | K30: OK | L30: OK | O30: OK | T30: =_xlfn.XLOOKUP(H30,#REF!,#REF!,0,0) -> #REF!
A31: SR955034 | B31: Mascolo Nicholas (IDG2502) | E31: Hewlett-Packard | F31: HP ZBook 15 G5 | G31: 43633 | H31: ITDGTOL00069317 | I31: 69317 | J31: Firenze2019 | K31: OK | N31: OK | T31: =_xlfn.XLOOKUP(H31,#REF!,#REF!,0,0) -> #REF!
A32: SR944381 | E32: Hewlett-Packard | F32: HP ZBook 15 G5 | G32: 43727 | H32: ITDGTOL00069447 | I32: 69447 | J32: Vercelli69447 | K32: OK | N32: OK | T32: =_xlfn.XLOOKUP(H32,#REF!,#REF!,0,0) -> #REF!
A33: SR961077 | B33: Chieppa, Giorgio (IDG2474) | E33: Hewlett-Packard | F33: HP ZBook 15 G5 | G33: 43727 | H33: ITDGTOL00069456 | I33: 69456 | J33: Trapani456 | K33: OK | L33: OK | N33: OK | T33: =_xlfn.XLOOKUP(H33,#REF!,#REF!,0,0) -> #REF!
A34: SR977720 | B34: Favole Riccardo (ITDGTOL00059822) | E34: Hewlett-Packard | F34: HP ZBook 15 G5 | G34: 43727 | H34: ITDGTOL00069462 | I34: 69462 | J34: Spagna69462 | K34: OK | N34: OK | T34: =_xlfn.XLOOKUP(H34,#REF!,#REF!,0,0) -> #REF!
A35: SR977721 | E35: Hewlett-Packard | F35: HP ZBook 15 G5 | G35: 43727 | H35: ITDGTOL00069463 | I35: 69463 | J35: Austria69463 | K35: OK | N35: OK | T35: =_xlfn.XLOOKUP(H35,#REF!,#REF!,0,0) -> #REF!
A36: SR978327 | E36: Hewlett-Packard | F36: HP ZBook 15 G5 | G36: 43727 | H36: ITDGTOL00069464 | I36: 69464 | J36: Africa69464 | K36: OK | N36: OK | T36: =_xlfn.XLOOKUP(H36,#REF!,#REF!,0,0) -> #REF!
A37: SR982031 | E37: Hewlett-Packard | F37: HP ZBook 15 G5 | G37: 43727 | H37: ITDGTOL00069465 | I37: 69465 | J37: Asia33 | K37: OK | N37: OK | T37: =_xlfn.XLOOKUP(H37,#REF!,#REF!,0,0) -> #REF!
A38: SR982037 | E38: Hewlett-Packard | F38: HP ZBook 15 G5 | G38: 43727 | H38: ITDGTOL00069466 | I38: 69466 | J38: Giappone66 | K38: OK | N38: OK | T38: =_xlfn.XLOOKUP(H38,#REF!,#REF!,0,0) -> #REF!
A39: SR983439 | E39: Hewlett-Packard | F39: HP ZBook 15 G5 | G39: 43727 | H39: ITDGTOL00069467 | I39: 69467 | J39: Ginevra33 | K39: OK | N39: OK | T39: =_xlfn.XLOOKUP(H39,#REF!,#REF!,0,0) -> #REF!
A40: SR983445 | B40: A disposizione | E40: Hewlett-Packard | F40: HP ZBook 15 G5 | G40: 43727 | H40: ITDGTOL00069468 | I40: 69468 | J40: Malta44 | K40: OK | N40: OK | T40: =_xlfn.XLOOKUP(H40,#REF!,#REF!,0,0) -> #REF!
...
